import qs from "qs";

import * as auth from "auth-provider";
import { useAuth } from "context/auth-context";
import { useCallback } from "react";

const apiUrl = process.env.REACT_APP_API_URL;

interface Config extends RequestInit {
  token?: string;
  data?: object;
}

export const http = async (
  endpoint: string,
  { data, token, headers, ...customConfig }: Config = {}
) => {
  const config = {
    method: "GET",
    headers: {
      Authorization: token ? `Bearer ${token}` : "",
      "Content-Type": data ? "application/json" : "",
    },
    ...customConfig,
  };
  if (config.method.toLocaleUpperCase() === "GET") {
    endpoint += `?${qs.stringify(data)}`;
  } else {
    config.body = JSON.stringify(data || {});
  }

  // axios 和 fetch 的表现不一样，axios可以直接在状态不为2XX的时候会抛出异常
  // 在fetch里，服务端返回的异常状态catch不会抛出异常，只有在断网的或者链接失败会触发catch
  // 所以需要手动Promise.reject
  return fetch(`${apiUrl}/${endpoint}`, config).then(async (response) => {
    if (response.status === 401) {
      auth.logout();
      window.location.reload();
      return Promise.reject({ message: "请重新登陆" });
    }
    const data = await response.json();
    if (response.ok) {
      return data;
    } else {
      return Promise.reject(data);
    }
  });
};

export const useHttp = () => {
  const { user } = useAuth();
  return useCallback(
    (...[endpoint, config]: Parameters<typeof http>) =>
      http(endpoint, { ...config, token: user?.token }),
    [user?.token]
  );
};
